---
layout: single
published: true
title:  "[JAVA] 예외 처리 try-catch "
categories: Java
date: 2024-02-06 20:42:11
toc: true
toc_sticky: true
tag:   
  - Java
  - 자바
  - 예외 처리 try-catch
---

## try-catch문

앞서 살펴본 예외들을 처리하기 위해 try-catch문을 사용해봅시다. 먼저 기본 구조를 살펴보겠습니다.

```java
try {
    <수행할 문장 1>;
    <수행할 문장 2>;
    ...
} catch(예외1) {
    <수행할 문장 A>;
    ...
} catch(예외2) {
    <수행할 문장 a>;
    ...
}
```

혹은 

```java
try {
    <수행할 문장 1>;
    <수행할 문장 2>;
    ...
} catch (예외1 | 예외2) {  // 둘 중 하나가 예외일 경우 A 수행 (멀티 catch)
    <수행할 문장 A>;
    ...
}
```

위 코드와 같이 두 형태의 catch문이 모두 가능합니다. 

첫 번째 코드의 try문 에서 예외가 발생하여 catch 예외1이 수행된다면 그 다음 예외2의 catch문은 수행되지 않습니다. 

그리고 try문 안의 수행할 문장 중 예외가 발생하지 않는다면 catch문 안의 내용은 수행되지 않습니다. 하지만 try문 수행 중 예외가 발생하면 catch문이 수행됩니다.

앞에서 봤던 오류를 다시 한 번 보고, 예외처리 해보겠습니다. 

```java
import java.io.BufferedReader;
import java.io.FileReader;
import java.io.IOException;

public class ExceptionSample {
	public static void main(String[] args) throws IOException {
		BufferedReader br = new BufferedReader(new FileReader("존재하지_않는_파일"));
		br.readLine();
		br.close();
	}
}
```

```java
...
public class ExceptionSample {
	public static void main(String[] args) {
		**try {**
			BufferedReader br = new BufferedReader(new FileReader("존재하지_않는_파일"));
			br.readLine();
			br.close();
		**} catch (IOException e) {**
			System.out.println("error message: " + e.getMessage());
		**}**
	}
}
```

예외처리 한 후의 코드를 실행해보면 다음과 같은 결과를 볼 수 있습니다. 

```java
error message: 존재하지_않는_파일 (No such file or directory)
```

try문 에서 FileNotFoundException이 발생하면 catch 문의 내용이 실행됩니다. 위 코드에서는 에러 메시지를 출력하고 있죠. 

다른 예시도 try-catch문을 사용하도록 수정해보겠습니다. 

0으로 숫자를 나눴을 때 ArithmeticException이 발생하지만, 이것은 UncheckedException이죠. 하지만 모든 에러는 예외처리가 필요하기 때문에 try-catch문으로 감싸주겠습니다. 

```java
public class DivideExceptionSample {
	public static void main(String[] args) {
		int result;
		try {
			result = 5 / 0;
		} catch (ArithmeticException e) {
			result = -1;
			System.out.println("숫자는 0으로 나눌 수 없습니다.");
		}
	}
}
```

```java
숫자는 0으로 나눌 수 없습니다.
```

이전처럼 예외처리를 하지 않았다면, 에러메시지가 출력되면서 프로그램이 종료되지만, 위 코드처럼 try-catch 처리를 해주면 에러 발생시 catch문이 실행됩니다. catch문에서는 예외 발생시 result에 -1을 대입하도록 했습니다. 

### 다중 catch문 작성시 주의사항

그리고 다중 catch문을 작성할 때 주의할 점은, 상위 예외클래스가 하위 예외 클래스보다 아래쪽에 위치해야한다는 것 입니다. 아래 코드를 한번 고쳐봅시다.

```java
try {
	(ArrayIndexOutOfBoundsException 발생)

	(NumberFormatException 발생)
} catch(Exception e) {
	예외처리1
} catch(ArrayIndexOutOfBoundsException e) {
	예외처리2    // 컴파일 오류
}
```

이 코드에서 ArrayIndexOutOfBoundsException 예외와 NumberFormatException 예외는 모두 Exception을 상속받기 때문에 첫번째 catch 블록만 선택되어 실행됩니다. 두번째 catch블록은 어떤 경우에라도 실행되지 않는 코드라는거죠. 위 코드는 다음과 같이 수정해야합니다.

```java
try {
	(ArrayIndexOutOfBoundsException 발생)

	(NumberFormatException 발생)
} catch(ArrayIndexOutOfBoundsException e) {
	예외처리1
} catch(Exception e) {
	예외처리2 
}
```

try 블록에서 ArrayIndexOutOfBoundsException이 발생하면 첫번째 catch 블록을 실행하고, 그 밖의 다른 예외가 발생하면 두 번째 catch 블록을 실행합니다. 

## finally

프로그램 수행 도중 에러가 발생하면 프로그램이 중단되거나 예외 처리에 의해 catch 구문이 실행됩니다. 하지만 어떤 예외가 발생하더라도 반드시 실행되는 부분이 있는데, 바로 **finally** 구문입니다. 

![Untitled](https://prod-files-secure.s3.us-west-2.amazonaws.com/e8f11927-b70c-4524-9227-a3efac08e7aa/bba2e328-9629-41fd-bf3c-d44836451618/Untitled.png)

```java
public class DivideExceptionSample {
    void finalMessage() {
        System.out.println("그럼 수고하세요.");
    }

    public static void main(String[] args) {
        DivideExceptionSample sample = new DivideExceptionSample();
        int result;
        try {
            result = 5 / 0;
            sample.finalMessage();       // 이 코드는 실행되지 않는다.
        } catch (ArithmeticException e) {
            result = -1;
            System.out.println("숫자는 0으로 나눌 수 없습니다.");
        } finally {
            sample.finalMessage();    // 이곳에서는 예외와 상관없이 무조건 수행된다.
        }
    }
}
```

위 코드에서 finally 구문을 사용했는데, 예상되는 출력값이 어떻게 될까요? 한번 고민해봅시다. 

그리고 위 try문에서 **`sample.finalMessage();`** 는 절대로 실행될 수 없습니다. 
왜냐하면 `result = 5 / 0;`가 실행되면서 ArithmeticException이 발생하여 catch 구문으로 예외처리가 넘어가기 때문입니다. 

만약 `result = 5 / 0;` 이후에 **`sample.finalMessage();`** 메소드가 반드시 실행되어야 한다면 이런 경우를 처리하기 위해 자바에서는 위와 같이 finally문을 사용합니다. 

결과는 아래와 같습니다.

```java
숫자는 0으로 나눌 수 없습니다.
그럼 수고하세요.
```

다시 한번 강조하면, finally문은 try 문장 수행 중 예외 발생 여부와 상관없이 무조건 실행됩니다. 따라서 코드를 실행하면 `sample.finalMessage();` 메서드가 수행되어 “그럼 수고하세요” 라는 문장이 출력됩니다.